Error Logs:
[ WARN:0@14.307] global ./modules/videoio/src/cap_gstreamer.cpp (2401) handleMessage OpenCV | GStreamer warning: Embedded video playback halted; module v4l2src0 reported: Cannot identify device '/dev/video0'.
[ WARN:0@14.307] global ./modules/videoio/src/cap_gstreamer.cpp (1356) open OpenCV | GStreamer warning: unable to start pipeline
[ WARN:0@14.307] global ./modules/videoio/src/cap_gstreamer.cpp (862) isPipelinePlaying OpenCV | GStreamer warning: GStreamer: pipeline have not been created
[ WARN:0@14.308] global ./modules/videoio/src/cap_v4l.cpp (902) open VIDEOIO(V4L2:/dev/video0): can't open camera by index
Error OpenCV(4.6.0) ./modules/imgproc/src/resize.cpp:4052: error: (-215:Assertion failed) !ssize.empty() in function 'resize'


File "/usr/local/lib/python3.11/dist-packages/keras/src/engine/training.py", line 2440, in predict_function  *
        return step_function(self, iterator)
    File "/usr/local/lib/python3.11/dist-packages/keras/src/engine/training.py", line 2425, in step_function  **
        outputs = model.distribute_strategy.run(run_step, args=(data,))
    File "/usr/local/lib/python3.11/dist-packages/keras/src/engine/training.py", line 2413, in run_step  **
        outputs = model.predict_step(data)
    File "/usr/local/lib/python3.11/dist-packages/keras/src/engine/training.py", line 2381, in predict_step
        return self(x, training=False)
    File "/usr/local/lib/python3.11/dist-packages/keras/src/utils/traceback_utils.py", line 70, in error_handler
        raise e.with_traceback(filtered_tb) from None
    File "/usr/local/lib/python3.11/dist-packages/keras/src/engine/input_spec.py", line 298, in assert_input_compatibility
        raise ValueError(

    ValueError: Input 0 of layer "sequential_4" is incompatible with the layer: expected shape=(None, 224, 224, 3), found shape=(32, 224, 3)

